Workbook

Sheet Combined
A1: Combined
A2: Combined view — use the Venture filter below
A4: Venture Filter: | B4: All
A5: Venture criteria (helper): | B5: =IF(B4="All","*",B4) -> *
A6: Week Ending (blank = all weeks):
A7: Week criteria (helper): | B7: =IF(B6="","*",B6) -> *
A9: This Week / Filtered Weekly Totals
A10: Leads added | B10: =SUMIFS(Weekly_Log!$G$2:$G$111,Weekly_Log!$B$2:$B$111,$B$5,Weekly_Log!$A$2:$A$111,$B$7) -> 5
A11: Outreach sent | B11: =SUMIFS(Weekly_Log!$H$2:$H$111,Weekly_Log!$B$2:$B$111,$B$5,Weekly_Log!$A$2:$A$111,$B$7) -> 14
A12: Follow-ups sent | B12: =SUMIFS(Weekly_Log!$I$2:$I$111,Weekly_Log!$B$2:$B$111,$B$5,Weekly_Log!$A$2:$A$111,$B$7) -> 6
A13: Positive replies | B13: =SUMIFS(Weekly_Log!$J$2:$J$111,Weekly_Log!$B$2:$B$111,$B$5,Weekly_Log!$A$2:$A$111,$B$7) -> 3
A14: Calls booked | B14: =SUMIFS(Weekly_Log!$K$2:$K$111,Weekly_Log!$B$2:$B$111,$B$5,Weekly_Log!$A$2:$A$111,$B$7) -> 2
A15: Previews created | B15: =SUMIFS(Weekly_Log!$L$2:$L$111,Weekly_Log!$B$2:$B$111,$B$5,Weekly_Log!$A$2:$A$111,$B$7) -> 2
A16: Previews sent | B16: =SUMIFS(Weekly_Log!$M$2:$M$111,Weekly_Log!$B$2:$B$111,$B$5,Weekly_Log!$A$2:$A$111,$B$7) -> 2
A17: Proposals sent | B17: =SUMIFS(Weekly_Log!$N$2:$N$111,Weekly_Log!$B$2:$B$111,$B$5,Weekly_Log!$A$2:$A$111,$B$7) -> 1
A18: Deposits received | B18: =SUMIFS(Weekly_Log!$O$2:$O$111,Weekly_Log!$B$2:$B$111,$B$5,Weekly_Log!$A$2:$A$111,$B$7) -> 1
A19: Deals won | B19: =SUMIFS(Weekly_Log!$P$2:$P$111,Weekly_Log!$B$2:$B$111,$B$5,Weekly_Log!$A$2:$A$111,$B$7) -> 0
A20: Deliverables completed | B20: =SUMIFS(Weekly_Log!$Q$2:$Q$111,Weekly_Log!$B$2:$B$111,$B$5,Weekly_Log!$A$2:$A$111,$B$7) -> 0
A21: Contracted revenue | B21: =SUMIFS(Weekly_Log!$R$2:$R$111,Weekly_Log!$B$2:$B$111,$B$5,Weekly_Log!$A$2:$A$111,$B$7) -> 0
A22: Cash collected | B22: =SUMIFS(Weekly_Log!$S$2:$S$111,Weekly_Log!$B$2:$B$111,$B$5,Weekly_Log!$A$2:$A$111,$B$7) -> 900
A23: Outstanding payments | B23: =SUMIFS(Weekly_Log!$T$2:$T$111,Weekly_Log!$B$2:$B$111,$B$5,Weekly_Log!$A$2:$A$111,$B$7) -> 900
A24: Active projects | B24: =SUMIFS(Weekly_Log!$U$2:$U$111,Weekly_Log!$B$2:$B$111,$B$5,Weekly_Log!$A$2:$A$111,$B$7) -> 2
A25: Overdue next actions | B25: =SUMIFS(Weekly_Log!$V$2:$V$111,Weekly_Log!$B$2:$B$111,$B$5,Weekly_Log!$A$2:$A$111,$B$7) -> 0
A27: Month-to-Date Totals (current calendar month)
A28: Leads added | B28: =SUMIFS(Weekly_Log!$G$2:$G$111,Weekly_Log!$B$2:$B$111,$B$5,Weekly_Log!$A$2:$A$111,">="&EOMONTH(TODAY(),-1)+1,Weekly_Log!$A$2:$A$111,"<="&EOMONTH(TODAY(),0)) -> 2
A29: Outreach sent | B29: =SUMIFS(Weekly_Log!$H$2:$H$111,Weekly_Log!$B$2:$B$111,$B$5,Weekly_Log!$A$2:$A$111,">="&EOMONTH(TODAY(),-1)+1,Weekly_Log!$A$2:$A$111,"<="&EOMONTH(TODAY(),0)) -> 6
A30: Follow-ups sent | B30: =SUMIFS(Weekly_Log!$I$2:$I$111,Weekly_Log!$B$2:$B$111,$B$5,Weekly_Log!$A$2:$A$111,">="&EOMONTH(TODAY(),-1)+1,Weekly_Log!$A$2:$A$111,"<="&EOMONTH(TODAY(),0)) -> 2
A31: Positive replies | B31: =SUMIFS(Weekly_Log!$J$2:$J$111,Weekly_Log!$B$2:$B$111,$B$5,Weekly_Log!$A$2:$A$111,">="&EOMONTH(TODAY(),-1)+1,Weekly_Log!$A$2:$A$111,"<="&EOMONTH(TODAY(),0)) -> 1
A32: Calls booked | B32: =SUMIFS(Weekly_Log!$K$2:$K$111,Weekly_Log!$B$2:$B$111,$B$5,Weekly_Log!$A$2:$A$111,">="&EOMONTH(TODAY(),-1)+1,Weekly_Log!$A$2:$A$111,"<="&EOMONTH(TODAY(),0)) -> 1
A33: Previews created | B33: =SUMIFS(Weekly_Log!$L$2:$L$111,Weekly_Log!$B$2:$B$111,$B$5,Weekly_Log!$A$2:$A$111,">="&EOMONTH(TODAY(),-1)+1,Weekly_Log!$A$2:$A$111,"<="&EOMONTH(TODAY(),0)) -> 1
A34: Previews sent | B34: =SUMIFS(Weekly_Log!$M$2:$M$111,Weekly_Log!$B$2:$B$111,$B$5,Weekly_Log!$A$2:$A$111,">="&EOMONTH(TODAY(),-1)+1,Weekly_Log!$A$2:$A$111,"<="&EOMONTH(TODAY(),0)) -> 1
A35: Proposals sent | B35: =SUMIFS(Weekly_Log!$N$2:$N$111,Weekly_Log!$B$2:$B$111,$B$5,Weekly_Log!$A$2:$A$111,">="&EOMONTH(TODAY(),-1)+1,Weekly_Log!$A$2:$A$111,"<="&EOMONTH(TODAY(),0)) -> 0
A36: Deposits received | B36: =SUMIFS(Weekly_Log!$O$2:$O$111,Weekly_Log!$B$2:$B$111,$B$5,Weekly_Log!$A$2:$A$111,">="&EOMONTH(TODAY(),-1)+1,Weekly_Log!$A$2:$A$111,"<="&EOMONTH(TODAY(),0)) -> 1
A37: Deals won | B37: =SUMIFS(Weekly_Log!$P$2:$P$111,Weekly_Log!$B$2:$B$111,$B$5,Weekly_Log!$A$2:$A$111,">="&EOMONTH(TODAY(),-1)+1,Weekly_Log!$A$2:$A$111,"<="&EOMONTH(TODAY(),0)) -> 0
A38: Deliverables completed | B38: =SUMIFS(Weekly_Log!$Q$2:$Q$111,Weekly_Log!$B$2:$B$111,$B$5,Weekly_Log!$A$2:$A$111,">="&EOMONTH(TODAY(),-1)+1,Weekly_Log!$A$2:$A$111,"<="&EOMONTH(TODAY(),0)) -> 0
A39: Contracted revenue | B39: =SUMIFS(Weekly_Log!$R$2:$R$111,Weekly_Log!$B$2:$B$111,$B$5,Weekly_Log!$A$2:$A$111,">="&EOMONTH(TODAY(),-1)+1,Weekly_Log!$A$2:$A$111,"<="&EOMONTH(TODAY(),0)) -> 0
A40: Cash collected | B40: =SUMIFS(Weekly_Log!$S$2:$S$111,Weekly_Log!$B$2:$B$111,$B$5,Weekly_Log!$A$2:$A$111,">="&EOMONTH(TODAY(),-1)+1,Weekly_Log!$A$2:$A$111,"<="&EOMONTH(TODAY(),0)) -> 900
A41: Outstanding payments | B41: =SUMIFS(Weekly_Log!$T$2:$T$111,Weekly_Log!$B$2:$B$111,$B$5,Weekly_Log!$A$2:$A$111,">="&EOMONTH(TODAY(),-1)+1,Weekly_Log!$A$2:$A$111,"<="&EOMONTH(TODAY(),0)) -> 900
A42: Active projects | B42: =SUMIFS(Weekly_Log!$U$2:$U$111,Weekly_Log!$B$2:$B$111,$B$5,Weekly_Log!$A$2:$A$111,">="&EOMONTH(TODAY(),-1)+1,Weekly_Log!$A$2:$A$111,"<="&EOMONTH(TODAY(),0)) -> 1
A43: Overdue next actions | B43: =SUMIFS(Weekly_Log!$V$2:$V$111,Weekly_Log!$B$2:$B$111,$B$5,Weekly_Log!$A$2:$A$111,">="&EOMONTH(TODAY(),-1)+1,Weekly_Log!$A$2:$A$111,"<="&EOMONTH(TODAY(),0)) -> 0
...

Sheet Web Development
A1: Web Development
A2: Venture-locked to Web Development
A4: Week Ending (blank = all weeks):
A5: Week criteria (helper): | B5: =IF(B4="","*",B4) -> *
A7: This Week / Filtered Weekly Totals
A8: Leads added | B8: =SUMIFS(Weekly_Log!$G$2:$G$111,Weekly_Log!$B$2:$B$111,"Web Development",Weekly_Log!$A$2:$A$111,$B$5) -> 3
A9: Outreach sent | B9: =SUMIFS(Weekly_Log!$H$2:$H$111,Weekly_Log!$B$2:$B$111,"Web Development",Weekly_Log!$A$2:$A$111,$B$5) -> 8
A10: Follow-ups sent | B10: =SUMIFS(Weekly_Log!$I$2:$I$111,Weekly_Log!$B$2:$B$111,"Web Development",Weekly_Log!$A$2:$A$111,$B$5) -> 4
A11: Positive replies | B11: =SUMIFS(Weekly_Log!$J$2:$J$111,Weekly_Log!$B$2:$B$111,"Web Development",Weekly_Log!$A$2:$A$111,$B$5) -> 2
A12: Calls booked | B12: =SUMIFS(Weekly_Log!$K$2:$K$111,Weekly_Log!$B$2:$B$111,"Web Development",Weekly_Log!$A$2:$A$111,$B$5) -> 1
A13: Previews created | B13: =SUMIFS(Weekly_Log!$L$2:$L$111,Weekly_Log!$B$2:$B$111,"Web Development",Weekly_Log!$A$2:$A$111,$B$5) -> 1
A14: Previews sent | B14: =SUMIFS(Weekly_Log!$M$2:$M$111,Weekly_Log!$B$2:$B$111,"Web Development",Weekly_Log!$A$2:$A$111,$B$5) -> 1
A15: Proposals sent | B15: =SUMIFS(Weekly_Log!$N$2:$N$111,Weekly_Log!$B$2:$B$111,"Web Development",Weekly_Log!$A$2:$A$111,$B$5) -> 1
A16: Deposits received | B16: =SUMIFS(Weekly_Log!$O$2:$O$111,Weekly_Log!$B$2:$B$111,"Web Development",Weekly_Log!$A$2:$A$111,$B$5) -> 0
A17: Deals won | B17: =SUMIFS(Weekly_Log!$P$2:$P$111,Weekly_Log!$B$2:$B$111,"Web Development",Weekly_Log!$A$2:$A$111,$B$5) -> 0
A18: Deliverables completed | B18: =SUMIFS(Weekly_Log!$Q$2:$Q$111,Weekly_Log!$B$2:$B$111,"Web Development",Weekly_Log!$A$2:$A$111,$B$5) -> 0
A19: Contracted revenue | B19: =SUMIFS(Weekly_Log!$R$2:$R$111,Weekly_Log!$B$2:$B$111,"Web Development",Weekly_Log!$A$2:$A$111,$B$5) -> 0
A20: Cash collected | B20: =SUMIFS(Weekly_Log!$S$2:$S$111,Weekly_Log!$B$2:$B$111,"Web Development",Weekly_Log!$A$2:$A$111,$B$5) -> 0
A21: Outstanding payments | B21: =SUMIFS(Weekly_Log!$T$2:$T$111,Weekly_Log!$B$2:$B$111,"Web Development",Weekly_Log!$A$2:$A$111,$B$5) -> 0
A22: Active projects | B22: =SUMIFS(Weekly_Log!$U$2:$U$111,Weekly_Log!$B$2:$B$111,"Web Development",Weekly_Log!$A$2:$A$111,$B$5) -> 1
A23: Overdue next actions | B23: =SUMIFS(Weekly_Log!$V$2:$V$111,Weekly_Log!$B$2:$B$111,"Web Development",Weekly_Log!$A$2:$A$111,$B$5) -> 0
A25: Month-to-Date Totals (current calendar month)
A26: Leads added | B26: =SUMIFS(Weekly_Log!$G$2:$G$111,Weekly_Log!$B$2:$B$111,"Web Development",Weekly_Log!$A$2:$A$111,">="&EOMONTH(TODAY(),-1)+1,Weekly_Log!$A$2:$A$111,"<="&EOMONTH(TODAY(),0)) -> 0
A27: Outreach sent | B27: =SUMIFS(Weekly_Log!$H$2:$H$111,Weekly_Log!$B$2:$B$111,"Web Development",Weekly_Log!$A$2:$A$111,">="&EOMONTH(TODAY(),-1)+1,Weekly_Log!$A$2:$A$111,"<="&EOMONTH(TODAY(),0)) -> 0
A28: Follow-ups sent | B28: =SUMIFS(Weekly_Log!$I$2:$I$111,Weekly_Log!$B$2:$B$111,"Web Development",Weekly_Log!$A$2:$A$111,">="&EOMONTH(TODAY(),-1)+1,Weekly_Log!$A$2:$A$111,"<="&EOMONTH(TODAY(),0)) -> 0
A29: Positive replies | B29: =SUMIFS(Weekly_Log!$J$2:$J$111,Weekly_Log!$B$2:$B$111,"Web Development",Weekly_Log!$A$2:$A$111,">="&EOMONTH(TODAY(),-1)+1,Weekly_Log!$A$2:$A$111,"<="&EOMONTH(TODAY(),0)) -> 0
A30: Calls booked | B30: =SUMIFS(Weekly_Log!$K$2:$K$111,Weekly_Log!$B$2:$B$111,"Web Development",Weekly_Log!$A$2:$A$111,">="&EOMONTH(TODAY(),-1)+1,Weekly_Log!$A$2:$A$111,"<="&EOMONTH(TODAY(),0)) -> 0
A31: Previews created | B31: =SUMIFS(Weekly_Log!$L$2:$L$111,Weekly_Log!$B$2:$B$111,"Web Development",Weekly_Log!$A$2:$A$111,">="&EOMONTH(TODAY(),-1)+1,Weekly_Log!$A$2:$A$111,"<="&EOMONTH(TODAY(),0)) -> 0
A32: Previews sent | B32: =SUMIFS(Weekly_Log!$M$2:$M$111,Weekly_Log!$B$2:$B$111,"Web Development",Weekly_Log!$A$2:$A$111,">="&EOMONTH(TODAY(),-1)+1,Weekly_Log!$A$2:$A$111,"<="&EOMONTH(TODAY(),0)) -> 0
A33: Proposals sent | B33: =SUMIFS(Weekly_Log!$N$2:$N$111,Weekly_Log!$B$2:$B$111,"Web Development",Weekly_Log!$A$2:$A$111,">="&EOMONTH(TODAY(),-1)+1,Weekly_Log!$A$2:$A$111,"<="&EOMONTH(TODAY(),0)) -> 0
A34: Deposits received | B34: =SUMIFS(Weekly_Log!$O$2:$O$111,Weekly_Log!$B$2:$B$111,"Web Development",Weekly_Log!$A$2:$A$111,">="&EOMONTH(TODAY(),-1)+1,Weekly_Log!$A$2:$A$111,"<="&EOMONTH(TODAY(),0)) -> 0
A35: Deals won | B35: =SUMIFS(Weekly_Log!$P$2:$P$111,Weekly_Log!$B$2:$B$111,"Web Development",Weekly_Log!$A$2:$A$111,">="&EOMONTH(TODAY(),-1)+1,Weekly_Log!$A$2:$A$111,"<="&EOMONTH(TODAY(),0)) -> 0
A36: Deliverables completed | B36: =SUMIFS(Weekly_Log!$Q$2:$Q$111,Weekly_Log!$B$2:$B$111,"Web Development",Weekly_Log!$A$2:$A$111,">="&EOMONTH(TODAY(),-1)+1,Weekly_Log!$A$2:$A$111,"<="&EOMONTH(TODAY(),0)) -> 0
A37: Contracted revenue | B37: =SUMIFS(Weekly_Log!$R$2:$R$111,Weekly_Log!$B$2:$B$111,"Web Development",Weekly_Log!$A$2:$A$111,">="&EOMONTH(TODAY(),-1)+1,Weekly_Log!$A$2:$A$111,"<="&EOMONTH(TODAY(),0)) -> 0
A38: Cash collected | B38: =SUMIFS(Weekly_Log!$S$2:$S$111,Weekly_Log!$B$2:$B$111,"Web Development",Weekly_Log!$A$2:$A$111,">="&EOMONTH(TODAY(),-1)+1,Weekly_Log!$A$2:$A$111,"<="&EOMONTH(TODAY(),0)) -> 0
A39: Outstanding payments | B39: =SUMIFS(Weekly_Log!$T$2:$T$111,Weekly_Log!$B$2:$B$111,"Web Development",Weekly_Log!$A$2:$A$111,">="&EOMONTH(TODAY(),-1)+1,Weekly_Log!$A$2:$A$111,"<="&EOMONTH(TODAY(),0)) -> 0
A40: Active projects | B40: =SUMIFS(Weekly_Log!$U$2:$U$111,Weekly_Log!$B$2:$B$111,"Web Development",Weekly_Log!$A$2:$A$111,">="&EOMONTH(TODAY(),-1)+1,Weekly_Log!$A$2:$A$111,"<="&EOMONTH(TODAY(),0)) -> 0
A41: Overdue next actions | B41: =SUMIFS(Weekly_Log!$V$2:$V$111,Weekly_Log!$B$2:$B$111,"Web Development",Weekly_Log!$A$2:$A$111,">="&EOMONTH(TODAY(),-1)+1,Weekly_Log!$A$2:$A$111,"<="&EOMONTH(TODAY(),0)) -> 0
A43: Targets & Progress (keep in sync with venture dashboards in Master CRM)
A44: Web Development monthly revenue target | B44: 4000
...

Sheet Cinematic Videos
A1: Cinematic Videos
A2: Venture-locked to Cinematic Videos
A4: Week Ending (blank = all weeks):
A5: Week criteria (helper): | B5: =IF(B4="","*",B4) -> *
A7: This Week / Filtered Weekly Totals
A8: Leads added | B8: =SUMIFS(Weekly_Log!$G$2:$G$111,Weekly_Log!$B$2:$B$111,"Cinematic Videos",Weekly_Log!$A$2:$A$111,$B$5) -> 2
A9: Outreach sent | B9: =SUMIFS(Weekly_Log!$H$2:$H$111,Weekly_Log!$B$2:$B$111,"Cinematic Videos",Weekly_Log!$A$2:$A$111,$B$5) -> 6
A10: Follow-ups sent | B10: =SUMIFS(Weekly_Log!$I$2:$I$111,Weekly_Log!$B$2:$B$111,"Cinematic Videos",Weekly_Log!$A$2:$A$111,$B$5) -> 2
A11: Positive replies | B11: =SUMIFS(Weekly_Log!$J$2:$J$111,Weekly_Log!$B$2:$B$111,"Cinematic Videos",Weekly_Log!$A$2:$A$111,$B$5) -> 1
A12: Calls booked | B12: =SUMIFS(Weekly_Log!$K$2:$K$111,Weekly_Log!$B$2:$B$111,"Cinematic Videos",Weekly_Log!$A$2:$A$111,$B$5) -> 1
A13: Previews created | B13: =SUMIFS(Weekly_Log!$L$2:$L$111,Weekly_Log!$B$2:$B$111,"Cinematic Videos",Weekly_Log!$A$2:$A$111,$B$5) -> 1
A14: Previews sent | B14: =SUMIFS(Weekly_Log!$M$2:$M$111,Weekly_Log!$B$2:$B$111,"Cinematic Videos",Weekly_Log!$A$2:$A$111,$B$5) -> 1
A15: Proposals sent | B15: =SUMIFS(Weekly_Log!$N$2:$N$111,Weekly_Log!$B$2:$B$111,"Cinematic Videos",Weekly_Log!$A$2:$A$111,$B$5) -> 0
A16: Deposits received | B16: =SUMIFS(Weekly_Log!$O$2:$O$111,Weekly_Log!$B$2:$B$111,"Cinematic Videos",Weekly_Log!$A$2:$A$111,$B$5) -> 1
A17: Deals won | B17: =SUMIFS(Weekly_Log!$P$2:$P$111,Weekly_Log!$B$2:$B$111,"Cinematic Videos",Weekly_Log!$A$2:$A$111,$B$5) -> 0
A18: Deliverables completed | B18: =SUMIFS(Weekly_Log!$Q$2:$Q$111,Weekly_Log!$B$2:$B$111,"Cinematic Videos",Weekly_Log!$A$2:$A$111,$B$5) -> 0
A19: Contracted revenue | B19: =SUMIFS(Weekly_Log!$R$2:$R$111,Weekly_Log!$B$2:$B$111,"Cinematic Videos",Weekly_Log!$A$2:$A$111,$B$5) -> 0
A20: Cash collected | B20: =SUMIFS(Weekly_Log!$S$2:$S$111,Weekly_Log!$B$2:$B$111,"Cinematic Videos",Weekly_Log!$A$2:$A$111,$B$5) -> 900
A21: Outstanding payments | B21: =SUMIFS(Weekly_Log!$T$2:$T$111,Weekly_Log!$B$2:$B$111,"Cinematic Videos",Weekly_Log!$A$2:$A$111,$B$5) -> 900
A22: Active projects | B22: =SUMIFS(Weekly_Log!$U$2:$U$111,Weekly_Log!$B$2:$B$111,"Cinematic Videos",Weekly_Log!$A$2:$A$111,$B$5) -> 1
A23: Overdue next actions | B23: =SUMIFS(Weekly_Log!$V$2:$V$111,Weekly_Log!$B$2:$B$111,"Cinematic Videos",Weekly_Log!$A$2:$A$111,$B$5) -> 0
A25: Month-to-Date Totals (current calendar month)
A26: Leads added | B26: =SUMIFS(Weekly_Log!$G$2:$G$111,Weekly_Log!$B$2:$B$111,"Cinematic Videos",Weekly_Log!$A$2:$A$111,">="&EOMONTH(TODAY(),-1)+1,Weekly_Log!$A$2:$A$111,"<="&EOMONTH(TODAY(),0)) -> 2
A27: Outreach sent | B27: =SUMIFS(Weekly_Log!$H$2:$H$111,Weekly_Log!$B$2:$B$111,"Cinematic Videos",Weekly_Log!$A$2:$A$111,">="&EOMONTH(TODAY(),-1)+1,Weekly_Log!$A$2:$A$111,"<="&EOMONTH(TODAY(),0)) -> 6
A28: Follow-ups sent | B28: =SUMIFS(Weekly_Log!$I$2:$I$111,Weekly_Log!$B$2:$B$111,"Cinematic Videos",Weekly_Log!$A$2:$A$111,">="&EOMONTH(TODAY(),-1)+1,Weekly_Log!$A$2:$A$111,"<="&EOMONTH(TODAY(),0)) -> 2
A29: Positive replies | B29: =SUMIFS(Weekly_Log!$J$2:$J$111,Weekly_Log!$B$2:$B$111,"Cinematic Videos",Weekly_Log!$A$2:$A$111,">="&EOMONTH(TODAY(),-1)+1,Weekly_Log!$A$2:$A$111,"<="&EOMONTH(TODAY(),0)) -> 1
A30: Calls booked | B30: =SUMIFS(Weekly_Log!$K$2:$K$111,Weekly_Log!$B$2:$B$111,"Cinematic Videos",Weekly_Log!$A$2:$A$111,">="&EOMONTH(TODAY(),-1)+1,Weekly_Log!$A$2:$A$111,"<="&EOMONTH(TODAY(),0)) -> 1
A31: Previews created | B31: =SUMIFS(Weekly_Log!$L$2:$L$111,Weekly_Log!$B$2:$B$111,"Cinematic Videos",Weekly_Log!$A$2:$A$111,">="&EOMONTH(TODAY(),-1)+1,Weekly_Log!$A$2:$A$111,"<="&EOMONTH(TODAY(),0)) -> 1
A32: Previews sent | B32: =SUMIFS(Weekly_Log!$M$2:$M$111,Weekly_Log!$B$2:$B$111,"Cinematic Videos",Weekly_Log!$A$2:$A$111,">="&EOMONTH(TODAY(),-1)+1,Weekly_Log!$A$2:$A$111,"<="&EOMONTH(TODAY(),0)) -> 1
A33: Proposals sent | B33: =SUMIFS(Weekly_Log!$N$2:$N$111,Weekly_Log!$B$2:$B$111,"Cinematic Videos",Weekly_Log!$A$2:$A$111,">="&EOMONTH(TODAY(),-1)+1,Weekly_Log!$A$2:$A$111,"<="&EOMONTH(TODAY(),0)) -> 0
A34: Deposits received | B34: =SUMIFS(Weekly_Log!$O$2:$O$111,Weekly_Log!$B$2:$B$111,"Cinematic Videos",Weekly_Log!$A$2:$A$111,">="&EOMONTH(TODAY(),-1)+1,Weekly_Log!$A$2:$A$111,"<="&EOMONTH(TODAY(),0)) -> 1
A35: Deals won | B35: =SUMIFS(Weekly_Log!$P$2:$P$111,Weekly_Log!$B$2:$B$111,"Cinematic Videos",Weekly_Log!$A$2:$A$111,">="&EOMONTH(TODAY(),-1)+1,Weekly_Log!$A$2:$A$111,"<="&EOMONTH(TODAY(),0)) -> 0
A36: Deliverables completed | B36: =SUMIFS(Weekly_Log!$Q$2:$Q$111,Weekly_Log!$B$2:$B$111,"Cinematic Videos",Weekly_Log!$A$2:$A$111,">="&EOMONTH(TODAY(),-1)+1,Weekly_Log!$A$2:$A$111,"<="&EOMONTH(TODAY(),0)) -> 0
A37: Contracted revenue | B37: =SUMIFS(Weekly_Log!$R$2:$R$111,Weekly_Log!$B$2:$B$111,"Cinematic Videos",Weekly_Log!$A$2:$A$111,">="&EOMONTH(TODAY(),-1)+1,Weekly_Log!$A$2:$A$111,"<="&EOMONTH(TODAY(),0)) -> 0
A38: Cash collected | B38: =SUMIFS(Weekly_Log!$S$2:$S$111,Weekly_Log!$B$2:$B$111,"Cinematic Videos",Weekly_Log!$A$2:$A$111,">="&EOMONTH(TODAY(),-1)+1,Weekly_Log!$A$2:$A$111,"<="&EOMONTH(TODAY(),0)) -> 900
A39: Outstanding payments | B39: =SUMIFS(Weekly_Log!$T$2:$T$111,Weekly_Log!$B$2:$B$111,"Cinematic Videos",Weekly_Log!$A$2:$A$111,">="&EOMONTH(TODAY(),-1)+1,Weekly_Log!$A$2:$A$111,"<="&EOMONTH(TODAY(),0)) -> 900
A40: Active projects | B40: =SUMIFS(Weekly_Log!$U$2:$U$111,Weekly_Log!$B$2:$B$111,"Cinematic Videos",Weekly_Log!$A$2:$A$111,">="&EOMONTH(TODAY(),-1)+1,Weekly_Log!$A$2:$A$111,"<="&EOMONTH(TODAY(),0)) -> 1
A41: Overdue next actions | B41: =SUMIFS(Weekly_Log!$V$2:$V$111,Weekly_Log!$B$2:$B$111,"Cinematic Videos",Weekly_Log!$A$2:$A$111,">="&EOMONTH(TODAY(),-1)+1,Weekly_Log!$A$2:$A$111,"<="&EOMONTH(TODAY(),0)) -> 0
A43: Targets & Progress (keep in sync with venture dashboards in Master CRM)
A44: Cinematic Videos monthly revenue target | B44: 4500
...

Sheet Weekly_Log
A1: Week Ending | B1: Venture | C1: Geography | D1: Vertical | E1: Pipeline Stage Focus | F1: Lead Tier Focus | G1: Leads Added | H1: Outreach Sent | I1: Follow-Ups Sent | J1: Positive Replies | K1: Calls Booked | L1: Previews Created | M1: Previews Sent | N1: Proposals Sent | O1: Deposits Received | P1: Deals Won | Q1: Deliverables Completed | R1: Contracted Revenue | S1: Cash Collected | T1: Outstanding Payments | U1: Active Projects | V1: Overdue Next Actions | W1: Notes
A2: 46265 | B2: Web Development | C2: Austin, TX | D2: Healthcare / Local Service | E2: Proposal Sent | F2: A | G2: 3 | H2: 8 | I2: 4 | J2: 2 | K2: 1 | L2: 1 | M2: 1 | N2: 1 | O2: 0 | P2: 0 | Q2: 0 | R2: 0 | S2: 0 | T2: 0 | U2: 1 | V2: 0 | W2: Example week — safe to delete. Riverside Dental proposal sent.
A3: 46272 | B3: Cinematic Videos | C3: Scottsdale, AZ | D3: Real Estate | E3: Verbal Yes | F3: A | G3: 2 | H3: 6 | I3: 2 | J3: 1 | K3: 1 | L3: 1 | M3: 1 | N3: 0 | O3: 1 | P3: 0 | Q3: 0 | R3: 0 | S3: 900 | T3: 900 | U3: 1 | V3: 0 | W3: Example week — safe to delete. Bluestone deposit invoice going out.

Sheet Lists
A1: Venture | B1: VentureFilter | C1: StageFocus | D1: TierFocus
A2: Web Development | B2: All | C2: Identified | D2: A
A3: Cinematic Videos | B3: Web Development | C3: Contacted | D3: B
B4: Cinematic Videos | C4: Follow-Up | D4: C
C5: Replied | D5: Mixed
C6: Qualified
C7: Preview Sent
C8: Call Booked
C9: Proposal Sent
C10: Verbal Yes
C11: Deposit Invoiced
C12: Deposit Paid
C13: Won
C14: Lost
C15: Nurture
C16: Multiple / Mixed
